2024-01-20 19:20:54,103 - ERROR - Unexpected error: "Attempt to overwrite 'filename' in LogRecord"
Traceback (most recent call last):
  File "C:\Users\filip\PycharmProjects\TP-backend\venv\lib\site-packages\starlette\middleware\base.py", line 78, in call_next
    message = await recv_stream.receive()
  File "C:\Users\filip\PycharmProjects\TP-backend\venv\lib\site-packages\anyio\streams\memory.py", line 98, in receive
    return self.receive_nowait()
  File "C:\Users\filip\PycharmProjects\TP-backend\venv\lib\site-packages\anyio\streams\memory.py", line 91, in receive_nowait
    raise EndOfStream
anyio.EndOfStream

During handling of the above exception, another exception occurred:

Traceback (most recent call last):
  File "C:\Users\filip\PycharmProjects\TP-backend\services\exceptionMiddleware.py", line 13, in dispatch
    return await call_next(request)
  File "C:\Users\filip\PycharmProjects\TP-backend\venv\lib\site-packages\starlette\middleware\base.py", line 84, in call_next
    raise app_exc
  File "C:\Users\filip\PycharmProjects\TP-backend\venv\lib\site-packages\starlette\middleware\base.py", line 70, in coro
    await self.app(scope, receive_or_disconnect, send_no_error)
  File "C:\Users\filip\PycharmProjects\TP-backend\venv\lib\site-packages\starlette\middleware\cors.py", line 91, in __call__
    await self.simple_response(scope, receive, send, request_headers=headers)
  File "C:\Users\filip\PycharmProjects\TP-backend\venv\lib\site-packages\starlette\middleware\cors.py", line 146, in simple_response
    await self.app(scope, receive, send)
  File "C:\Users\filip\PycharmProjects\TP-backend\venv\lib\site-packages\starlette\middleware\exceptions.py", line 79, in __call__
    raise exc
  File "C:\Users\filip\PycharmProjects\TP-backend\venv\lib\site-packages\starlette\middleware\exceptions.py", line 68, in __call__
    await self.app(scope, receive, sender)
  File "C:\Users\filip\PycharmProjects\TP-backend\venv\lib\site-packages\fastapi\middleware\asyncexitstack.py", line 20, in __call__
    raise e
  File "C:\Users\filip\PycharmProjects\TP-backend\venv\lib\site-packages\fastapi\middleware\asyncexitstack.py", line 17, in __call__
    await self.app(scope, receive, send)
  File "C:\Users\filip\PycharmProjects\TP-backend\venv\lib\site-packages\starlette\routing.py", line 718, in __call__
    await route.handle(scope, receive, send)
  File "C:\Users\filip\PycharmProjects\TP-backend\venv\lib\site-packages\starlette\routing.py", line 276, in handle
    await self.app(scope, receive, send)
  File "C:\Users\filip\PycharmProjects\TP-backend\venv\lib\site-packages\starlette\routing.py", line 66, in app
    response = await func(request)
  File "C:\Users\filip\PycharmProjects\TP-backend\venv\lib\site-packages\fastapi\routing.py", line 274, in app
    raw_response = await run_endpoint_function(
  File "C:\Users\filip\PycharmProjects\TP-backend\venv\lib\site-packages\fastapi\routing.py", line 191, in run_endpoint_function
    return await dependant.call(**values)
  File "C:\Users\filip\PycharmProjects\TP-backend\main.py", line 34, in get_gpx
    logger.info(f'File was find and returned: {filename}', extra={'filename': filename})
  File "C:\Users\filip\AppData\Local\Programs\Python\Python39\lib\logging\__init__.py", line 1446, in info
    self._log(INFO, msg, args, **kwargs)
  File "C:\Users\filip\AppData\Local\Programs\Python\Python39\lib\logging\__init__.py", line 1587, in _log
    record = self.makeRecord(self.name, level, fn, lno, msg, args,
  File "C:\Users\filip\AppData\Local\Programs\Python\Python39\lib\logging\__init__.py", line 1561, in makeRecord
    raise KeyError("Attempt to overwrite %r in LogRecord" % key)
KeyError: "Attempt to overwrite 'filename' in LogRecord"
2024-01-20 19:20:54,103 - ERROR - Unexpected error: "Attempt to overwrite 'filename' in LogRecord"
Traceback (most recent call last):
  File "C:\Users\filip\PycharmProjects\TP-backend\venv\lib\site-packages\starlette\middleware\base.py", line 78, in call_next
    message = await recv_stream.receive()
  File "C:\Users\filip\PycharmProjects\TP-backend\venv\lib\site-packages\anyio\streams\memory.py", line 98, in receive
    return self.receive_nowait()
  File "C:\Users\filip\PycharmProjects\TP-backend\venv\lib\site-packages\anyio\streams\memory.py", line 91, in receive_nowait
    raise EndOfStream
anyio.EndOfStream

During handling of the above exception, another exception occurred:

Traceback (most recent call last):
  File "C:\Users\filip\PycharmProjects\TP-backend\services\exceptionMiddleware.py", line 13, in dispatch
    return await call_next(request)
  File "C:\Users\filip\PycharmProjects\TP-backend\venv\lib\site-packages\starlette\middleware\base.py", line 84, in call_next
    raise app_exc
  File "C:\Users\filip\PycharmProjects\TP-backend\venv\lib\site-packages\starlette\middleware\base.py", line 70, in coro
    await self.app(scope, receive_or_disconnect, send_no_error)
  File "C:\Users\filip\PycharmProjects\TP-backend\venv\lib\site-packages\starlette\middleware\cors.py", line 91, in __call__
    await self.simple_response(scope, receive, send, request_headers=headers)
  File "C:\Users\filip\PycharmProjects\TP-backend\venv\lib\site-packages\starlette\middleware\cors.py", line 146, in simple_response
    await self.app(scope, receive, send)
  File "C:\Users\filip\PycharmProjects\TP-backend\venv\lib\site-packages\starlette\middleware\exceptions.py", line 79, in __call__
    raise exc
  File "C:\Users\filip\PycharmProjects\TP-backend\venv\lib\site-packages\starlette\middleware\exceptions.py", line 68, in __call__
    await self.app(scope, receive, sender)
  File "C:\Users\filip\PycharmProjects\TP-backend\venv\lib\site-packages\fastapi\middleware\asyncexitstack.py", line 20, in __call__
    raise e
  File "C:\Users\filip\PycharmProjects\TP-backend\venv\lib\site-packages\fastapi\middleware\asyncexitstack.py", line 17, in __call__
    await self.app(scope, receive, send)
  File "C:\Users\filip\PycharmProjects\TP-backend\venv\lib\site-packages\starlette\routing.py", line 718, in __call__
    await route.handle(scope, receive, send)
  File "C:\Users\filip\PycharmProjects\TP-backend\venv\lib\site-packages\starlette\routing.py", line 276, in handle
    await self.app(scope, receive, send)
  File "C:\Users\filip\PycharmProjects\TP-backend\venv\lib\site-packages\starlette\routing.py", line 66, in app
    response = await func(request)
  File "C:\Users\filip\PycharmProjects\TP-backend\venv\lib\site-packages\fastapi\routing.py", line 274, in app
    raw_response = await run_endpoint_function(
  File "C:\Users\filip\PycharmProjects\TP-backend\venv\lib\site-packages\fastapi\routing.py", line 191, in run_endpoint_function
    return await dependant.call(**values)
  File "C:\Users\filip\PycharmProjects\TP-backend\main.py", line 34, in get_gpx
    logger.info(f'File was find and returned: {filename}', extra={'filename': filename})
  File "C:\Users\filip\AppData\Local\Programs\Python\Python39\lib\logging\__init__.py", line 1446, in info
    self._log(INFO, msg, args, **kwargs)
  File "C:\Users\filip\AppData\Local\Programs\Python\Python39\lib\logging\__init__.py", line 1587, in _log
    record = self.makeRecord(self.name, level, fn, lno, msg, args,
  File "C:\Users\filip\AppData\Local\Programs\Python\Python39\lib\logging\__init__.py", line 1561, in makeRecord
    raise KeyError("Attempt to overwrite %r in LogRecord" % key)
KeyError: "Attempt to overwrite 'filename' in LogRecord"
2024-01-20 19:20:54,103 - ERROR - Unexpected error: "Attempt to overwrite 'filename' in LogRecord"
Traceback (most recent call last):
  File "C:\Users\filip\PycharmProjects\TP-backend\venv\lib\site-packages\starlette\middleware\base.py", line 78, in call_next
    message = await recv_stream.receive()
  File "C:\Users\filip\PycharmProjects\TP-backend\venv\lib\site-packages\anyio\streams\memory.py", line 98, in receive
    return self.receive_nowait()
  File "C:\Users\filip\PycharmProjects\TP-backend\venv\lib\site-packages\anyio\streams\memory.py", line 91, in receive_nowait
    raise EndOfStream
anyio.EndOfStream

During handling of the above exception, another exception occurred:

Traceback (most recent call last):
  File "C:\Users\filip\PycharmProjects\TP-backend\services\exceptionMiddleware.py", line 13, in dispatch
    return await call_next(request)
  File "C:\Users\filip\PycharmProjects\TP-backend\venv\lib\site-packages\starlette\middleware\base.py", line 84, in call_next
    raise app_exc
  File "C:\Users\filip\PycharmProjects\TP-backend\venv\lib\site-packages\starlette\middleware\base.py", line 70, in coro
    await self.app(scope, receive_or_disconnect, send_no_error)
  File "C:\Users\filip\PycharmProjects\TP-backend\venv\lib\site-packages\starlette\middleware\cors.py", line 91, in __call__
    await self.simple_response(scope, receive, send, request_headers=headers)
  File "C:\Users\filip\PycharmProjects\TP-backend\venv\lib\site-packages\starlette\middleware\cors.py", line 146, in simple_response
    await self.app(scope, receive, send)
  File "C:\Users\filip\PycharmProjects\TP-backend\venv\lib\site-packages\starlette\middleware\exceptions.py", line 79, in __call__
    raise exc
  File "C:\Users\filip\PycharmProjects\TP-backend\venv\lib\site-packages\starlette\middleware\exceptions.py", line 68, in __call__
    await self.app(scope, receive, sender)
  File "C:\Users\filip\PycharmProjects\TP-backend\venv\lib\site-packages\fastapi\middleware\asyncexitstack.py", line 20, in __call__
    raise e
  File "C:\Users\filip\PycharmProjects\TP-backend\venv\lib\site-packages\fastapi\middleware\asyncexitstack.py", line 17, in __call__
    await self.app(scope, receive, send)
  File "C:\Users\filip\PycharmProjects\TP-backend\venv\lib\site-packages\starlette\routing.py", line 718, in __call__
    await route.handle(scope, receive, send)
  File "C:\Users\filip\PycharmProjects\TP-backend\venv\lib\site-packages\starlette\routing.py", line 276, in handle
    await self.app(scope, receive, send)
  File "C:\Users\filip\PycharmProjects\TP-backend\venv\lib\site-packages\starlette\routing.py", line 66, in app
    response = await func(request)
  File "C:\Users\filip\PycharmProjects\TP-backend\venv\lib\site-packages\fastapi\routing.py", line 274, in app
    raw_response = await run_endpoint_function(
  File "C:\Users\filip\PycharmProjects\TP-backend\venv\lib\site-packages\fastapi\routing.py", line 191, in run_endpoint_function
    return await dependant.call(**values)
  File "C:\Users\filip\PycharmProjects\TP-backend\main.py", line 34, in get_gpx
    logger.info(f'File was find and returned: {filename}', extra={'filename': filename})
  File "C:\Users\filip\AppData\Local\Programs\Python\Python39\lib\logging\__init__.py", line 1446, in info
    self._log(INFO, msg, args, **kwargs)
  File "C:\Users\filip\AppData\Local\Programs\Python\Python39\lib\logging\__init__.py", line 1587, in _log
    record = self.makeRecord(self.name, level, fn, lno, msg, args,
  File "C:\Users\filip\AppData\Local\Programs\Python\Python39\lib\logging\__init__.py", line 1561, in makeRecord
    raise KeyError("Attempt to overwrite %r in LogRecord" % key)
KeyError: "Attempt to overwrite 'filename' in LogRecord"
2024-01-20 19:25:39,616 - ERROR - Unexpected error: File at path C:\Users\filip\PycharmProjects\TP-backend\storsage\gpx\hesoyam.gpx does not exist.
Traceback (most recent call last):
  File "C:\Users\filip\PycharmProjects\TP-backend\venv\lib\site-packages\anyio\streams\memory.py", line 98, in receive
    return self.receive_nowait()
  File "C:\Users\filip\PycharmProjects\TP-backend\venv\lib\site-packages\anyio\streams\memory.py", line 93, in receive_nowait
    raise WouldBlock
anyio.WouldBlock

During handling of the above exception, another exception occurred:

Traceback (most recent call last):
  File "C:\Users\filip\PycharmProjects\TP-backend\venv\lib\site-packages\starlette\middleware\base.py", line 78, in call_next
    message = await recv_stream.receive()
  File "C:\Users\filip\PycharmProjects\TP-backend\venv\lib\site-packages\anyio\streams\memory.py", line 118, in receive
    raise EndOfStream
anyio.EndOfStream

During handling of the above exception, another exception occurred:

Traceback (most recent call last):
  File "C:\Users\filip\PycharmProjects\TP-backend\services\exceptionMiddleware.py", line 13, in dispatch
    return await call_next(request)
  File "C:\Users\filip\PycharmProjects\TP-backend\venv\lib\site-packages\starlette\middleware\base.py", line 84, in call_next
    raise app_exc
  File "C:\Users\filip\PycharmProjects\TP-backend\venv\lib\site-packages\starlette\middleware\base.py", line 70, in coro
    await self.app(scope, receive_or_disconnect, send_no_error)
  File "C:\Users\filip\PycharmProjects\TP-backend\venv\lib\site-packages\starlette\middleware\cors.py", line 91, in __call__
    await self.simple_response(scope, receive, send, request_headers=headers)
  File "C:\Users\filip\PycharmProjects\TP-backend\venv\lib\site-packages\starlette\middleware\cors.py", line 146, in simple_response
    await self.app(scope, receive, send)
  File "C:\Users\filip\PycharmProjects\TP-backend\venv\lib\site-packages\starlette\middleware\exceptions.py", line 79, in __call__
    raise exc
  File "C:\Users\filip\PycharmProjects\TP-backend\venv\lib\site-packages\starlette\middleware\exceptions.py", line 68, in __call__
    await self.app(scope, receive, sender)
  File "C:\Users\filip\PycharmProjects\TP-backend\venv\lib\site-packages\fastapi\middleware\asyncexitstack.py", line 20, in __call__
    raise e
  File "C:\Users\filip\PycharmProjects\TP-backend\venv\lib\site-packages\fastapi\middleware\asyncexitstack.py", line 17, in __call__
    await self.app(scope, receive, send)
  File "C:\Users\filip\PycharmProjects\TP-backend\venv\lib\site-packages\starlette\routing.py", line 718, in __call__
    await route.handle(scope, receive, send)
  File "C:\Users\filip\PycharmProjects\TP-backend\venv\lib\site-packages\starlette\routing.py", line 276, in handle
    await self.app(scope, receive, send)
  File "C:\Users\filip\PycharmProjects\TP-backend\venv\lib\site-packages\starlette\routing.py", line 69, in app
    await response(scope, receive, send)
  File "C:\Users\filip\PycharmProjects\TP-backend\venv\lib\site-packages\starlette\responses.py", line 338, in __call__
    raise RuntimeError(f"File at path {self.path} does not exist.")
RuntimeError: File at path C:\Users\filip\PycharmProjects\TP-backend\storsage\gpx\hesoyam.gpx does not exist.
2024-01-20 19:25:39,616 - ERROR - Unexpected error: File at path C:\Users\filip\PycharmProjects\TP-backend\storsage\gpx\hesoyam.gpx does not exist.
Traceback (most recent call last):
  File "C:\Users\filip\PycharmProjects\TP-backend\venv\lib\site-packages\anyio\streams\memory.py", line 98, in receive
    return self.receive_nowait()
  File "C:\Users\filip\PycharmProjects\TP-backend\venv\lib\site-packages\anyio\streams\memory.py", line 93, in receive_nowait
    raise WouldBlock
anyio.WouldBlock

During handling of the above exception, another exception occurred:

Traceback (most recent call last):
  File "C:\Users\filip\PycharmProjects\TP-backend\venv\lib\site-packages\starlette\middleware\base.py", line 78, in call_next
    message = await recv_stream.receive()
  File "C:\Users\filip\PycharmProjects\TP-backend\venv\lib\site-packages\anyio\streams\memory.py", line 118, in receive
    raise EndOfStream
anyio.EndOfStream

During handling of the above exception, another exception occurred:

Traceback (most recent call last):
  File "C:\Users\filip\PycharmProjects\TP-backend\services\exceptionMiddleware.py", line 13, in dispatch
    return await call_next(request)
  File "C:\Users\filip\PycharmProjects\TP-backend\venv\lib\site-packages\starlette\middleware\base.py", line 84, in call_next
    raise app_exc
  File "C:\Users\filip\PycharmProjects\TP-backend\venv\lib\site-packages\starlette\middleware\base.py", line 70, in coro
    await self.app(scope, receive_or_disconnect, send_no_error)
  File "C:\Users\filip\PycharmProjects\TP-backend\venv\lib\site-packages\starlette\middleware\cors.py", line 91, in __call__
    await self.simple_response(scope, receive, send, request_headers=headers)
  File "C:\Users\filip\PycharmProjects\TP-backend\venv\lib\site-packages\starlette\middleware\cors.py", line 146, in simple_response
    await self.app(scope, receive, send)
  File "C:\Users\filip\PycharmProjects\TP-backend\venv\lib\site-packages\starlette\middleware\exceptions.py", line 79, in __call__
    raise exc
  File "C:\Users\filip\PycharmProjects\TP-backend\venv\lib\site-packages\starlette\middleware\exceptions.py", line 68, in __call__
    await self.app(scope, receive, sender)
  File "C:\Users\filip\PycharmProjects\TP-backend\venv\lib\site-packages\fastapi\middleware\asyncexitstack.py", line 20, in __call__
    raise e
  File "C:\Users\filip\PycharmProjects\TP-backend\venv\lib\site-packages\fastapi\middleware\asyncexitstack.py", line 17, in __call__
    await self.app(scope, receive, send)
  File "C:\Users\filip\PycharmProjects\TP-backend\venv\lib\site-packages\starlette\routing.py", line 718, in __call__
    await route.handle(scope, receive, send)
  File "C:\Users\filip\PycharmProjects\TP-backend\venv\lib\site-packages\starlette\routing.py", line 276, in handle
    await self.app(scope, receive, send)
  File "C:\Users\filip\PycharmProjects\TP-backend\venv\lib\site-packages\starlette\routing.py", line 69, in app
    await response(scope, receive, send)
  File "C:\Users\filip\PycharmProjects\TP-backend\venv\lib\site-packages\starlette\responses.py", line 338, in __call__
    raise RuntimeError(f"File at path {self.path} does not exist.")
RuntimeError: File at path C:\Users\filip\PycharmProjects\TP-backend\storsage\gpx\hesoyam.gpx does not exist.
2024-01-20 19:25:39,616 - ERROR - Unexpected error: File at path C:\Users\filip\PycharmProjects\TP-backend\storsage\gpx\hesoyam.gpx does not exist.
Traceback (most recent call last):
  File "C:\Users\filip\PycharmProjects\TP-backend\venv\lib\site-packages\anyio\streams\memory.py", line 98, in receive
    return self.receive_nowait()
  File "C:\Users\filip\PycharmProjects\TP-backend\venv\lib\site-packages\anyio\streams\memory.py", line 93, in receive_nowait
    raise WouldBlock
anyio.WouldBlock

During handling of the above exception, another exception occurred:

Traceback (most recent call last):
  File "C:\Users\filip\PycharmProjects\TP-backend\venv\lib\site-packages\starlette\middleware\base.py", line 78, in call_next
    message = await recv_stream.receive()
  File "C:\Users\filip\PycharmProjects\TP-backend\venv\lib\site-packages\anyio\streams\memory.py", line 118, in receive
    raise EndOfStream
anyio.EndOfStream

During handling of the above exception, another exception occurred:

Traceback (most recent call last):
  File "C:\Users\filip\PycharmProjects\TP-backend\services\exceptionMiddleware.py", line 13, in dispatch
    return await call_next(request)
  File "C:\Users\filip\PycharmProjects\TP-backend\venv\lib\site-packages\starlette\middleware\base.py", line 84, in call_next
    raise app_exc
  File "C:\Users\filip\PycharmProjects\TP-backend\venv\lib\site-packages\starlette\middleware\base.py", line 70, in coro
    await self.app(scope, receive_or_disconnect, send_no_error)
  File "C:\Users\filip\PycharmProjects\TP-backend\venv\lib\site-packages\starlette\middleware\cors.py", line 91, in __call__
    await self.simple_response(scope, receive, send, request_headers=headers)
  File "C:\Users\filip\PycharmProjects\TP-backend\venv\lib\site-packages\starlette\middleware\cors.py", line 146, in simple_response
    await self.app(scope, receive, send)
  File "C:\Users\filip\PycharmProjects\TP-backend\venv\lib\site-packages\starlette\middleware\exceptions.py", line 79, in __call__
    raise exc
  File "C:\Users\filip\PycharmProjects\TP-backend\venv\lib\site-packages\starlette\middleware\exceptions.py", line 68, in __call__
    await self.app(scope, receive, sender)
  File "C:\Users\filip\PycharmProjects\TP-backend\venv\lib\site-packages\fastapi\middleware\asyncexitstack.py", line 20, in __call__
    raise e
  File "C:\Users\filip\PycharmProjects\TP-backend\venv\lib\site-packages\fastapi\middleware\asyncexitstack.py", line 17, in __call__
    await self.app(scope, receive, send)
  File "C:\Users\filip\PycharmProjects\TP-backend\venv\lib\site-packages\starlette\routing.py", line 718, in __call__
    await route.handle(scope, receive, send)
  File "C:\Users\filip\PycharmProjects\TP-backend\venv\lib\site-packages\starlette\routing.py", line 276, in handle
    await self.app(scope, receive, send)
  File "C:\Users\filip\PycharmProjects\TP-backend\venv\lib\site-packages\starlette\routing.py", line 69, in app
    await response(scope, receive, send)
  File "C:\Users\filip\PycharmProjects\TP-backend\venv\lib\site-packages\starlette\responses.py", line 338, in __call__
    raise RuntimeError(f"File at path {self.path} does not exist.")
RuntimeError: File at path C:\Users\filip\PycharmProjects\TP-backend\storsage\gpx\hesoyam.gpx does not exist.
